<?xml version="1.0"?>
<robot name="simple_arm">

  <link name="base_link"/>

  <link name="link1">
    <visual>
      <origin xyz="0 0 0.15" rpy="0 0 0"/>
      <geometry>
        <cylinder length="0.30" radius="0.03"/>
      </geometry>
    </visual>
  </link>

  <joint name="joint1" type="revolute">
    <parent link="base_link"/>
    <child link="link1"/>
    <origin xyz="0 0 0" rpy="0 0 0"/>
    <axis xyz="0 0 1"/>
    <limit lower="-3.14" upper="3.14" effort="5.0" velocity="1.0"/>
  </joint>
  
  <link name="link2">
    <visual>
      <origin xyz="0 0 0.15" rpy="0 0 0"/>
      <geometry>
        <cylinder length="0.30" radius="0.03"/>
      </geometry>
    </visual>
  </link>

  <joint name="joint2" type="revolute">
    <parent link="link1"/>
    <child link="link2"/>
    <origin xyz="0 0 0.30" rpy="0 0 0"/>
    <axis xyz="0 1 0"/>
    <limit lower="-3.14" upper="3.14" effort="5.0" velocity="1.0"/>
  </joint>

    <link name="link3">
    <visual>
      <origin xyz="0 0 0.15" rpy="0 0 0"/>
      <geometry>
        <cylinder length="0.30" radius="0.03"/>
      </geometry>
    </visual>
  </link>

  <joint name="joint3" type="revolute">
    <parent link="link2"/>
    <child link="link3"/>
    <origin xyz="0 0 0.30" rpy="0 0 0"/>
    <axis xyz="1 0 0"/>
    <limit lower="-3.14" upper="3.14" effort="5.0" velocity="1.0"/>
  </joint>


  <!-- ros2_control: fake hardware so you can test controllers without Gazebo/hardware -->
    <ros2_control name="SimpleArmSystem" type="system">
    <hardware>
      <plugin>mock_components/GenericSystem</plugin>
    </hardware>

    <joint name="joint1">
      <command_interface name="position"/>
      <state_interface name="position"/>
      <state_interface name="velocity"/>
    </joint>

    <joint name="joint2">
      <command_interface name="position"/>
      <state_interface name="position"/>
      <state_interface name="velocity"/>
    </joint>

    <joint name="joint3">
      <command_interface name="position"/>
      <state_interface name="position"/>
      <state_interface name="velocity"/>
    </joint>

  </ros2_control>


  <!-- transmission is expected by many control setups -->
  <transmission name="joint1_transmission">
    <type>transmission_interface/SimpleTransmission</type>
    <joint name="joint1">
      <hardwareInterface>hardware_interface/position</hardwareInterface>
    </joint>
    <actuator name="joint1_motor">
      <hardwareInterface>hardware_interface/position</hardwareInterface>
      <mechanicalReduction>1</mechanicalReduction>
    </actuator>
  </transmission>

    <transmission name="joint2_transmission">
    <type>transmission_interface/SimpleTransmission</type>
    <joint name="joint2">
      <hardwareInterface>hardware_interface/position</hardwareInterface>
    </joint>
    <actuator name="joint2_motor">
      <hardwareInterface>hardware_interface/position</hardwareInterface>
      <mechanicalReduction>1</mechanicalReduction>
    </actuator>
  </transmission>

  <transmission name="joint3_transmission">
    <type>transmission_interface/SimpleTransmission</type>
    <joint name="joint3">
      <hardwareInterface>hardware_interface/position</hardwareInterface>
    </joint>
    <actuator name="joint3_motor">
      <hardwareInterface>hardware_interface/position</hardwareInterface>
      <mechanicalReduction>1</mechanicalReduction>
    </actuator>
  </transmission>

  

</robot>
